[2024-11-28 23:18:35,755] ERROR log_exception() L875  Exception on /produtos [GET] - call_trace=C:\Users\tiago\AppData\Local\Programs\Python\Python313\Lib\site-packages\flask\app.py L875 
Traceback (most recent call last):
  File "C:\Users\tiago\AppData\Local\Programs\Python\Python313\Lib\site-packages\flask\app.py", line 1511, in wsgi_app
    response = self.full_dispatch_request()
  File "C:\Users\tiago\AppData\Local\Programs\Python\Python313\Lib\site-packages\flask\app.py", line 919, in full_dispatch_request
    rv = self.handle_user_exception(e)
  File "C:\Users\tiago\AppData\Local\Programs\Python\Python313\Lib\site-packages\flask_cors\extension.py", line 194, in wrapped_function
    return cors_after_request(app.make_response(f(*args, **kwargs)))
                                                ~^^^^^^^^^^^^^^^^^
  File "C:\Users\tiago\AppData\Local\Programs\Python\Python313\Lib\site-packages\flask\app.py", line 917, in full_dispatch_request
    rv = self.dispatch_request()
  File "C:\Users\tiago\AppData\Local\Programs\Python\Python313\Lib\site-packages\flask\app.py", line 902, in dispatch_request
    return self.ensure_sync(self.view_functions[rule.endpoint])(**view_args)  # type: ignore[no-any-return]
           ~~~~~~~~~~~~~~~~~~~~~~~~~~~~~~~~~~~~~~~~~~~~~~~~~~~~^^^^^^^^^^^^^
  File "C:\Users\tiago\AppData\Local\Programs\Python\Python313\Lib\site-packages\flask_openapi3\scaffold.py", line 117, in view_func
    response = func(**func_kwargs)
  File "D:\Tiago\PUCRio\mvp\api_slc\app.py", line 80, in get_produtos
    logger.debug(f"%d produtos encontrados" % len(produtos))
                                              ~~~^^^^^^^^^^
TypeError: object of type 'Produto' has no len()
[2024-11-28 23:18:35,768] INFO _log() L97   127.0.0.1 - - [28/Nov/2024 23:18:35] "[35m[1mGET /produtos?id_lista=1 HTTP/1.1[0m" 500 - - call_trace=C:\Users\tiago\AppData\Local\Programs\Python\Python313\Lib\site-packages\werkzeug\_internal.py L97  
[2024-11-28 23:19:59,625] INFO _log() L97   [31m[1mWARNING: This is a development server. Do not use it in a production deployment. Use a production WSGI server instead.[0m
 * Running on all addresses (0.0.0.0)
 * Running on http://127.0.0.1:5000
 * Running on http://192.168.1.73:5000 - call_trace=C:\Users\tiago\AppData\Local\Programs\Python\Python313\Lib\site-packages\werkzeug\_internal.py L97  
[2024-11-28 23:19:59,626] INFO _log() L97   [33mPress CTRL+C to quit[0m - call_trace=C:\Users\tiago\AppData\Local\Programs\Python\Python313\Lib\site-packages\werkzeug\_internal.py L97  
[2024-11-28 23:20:03,597] ERROR log_exception() L875  Exception on /produtos [GET] - call_trace=C:\Users\tiago\AppData\Local\Programs\Python\Python313\Lib\site-packages\flask\app.py L875 
Traceback (most recent call last):
  File "C:\Users\tiago\AppData\Local\Programs\Python\Python313\Lib\site-packages\flask\app.py", line 1511, in wsgi_app
    response = self.full_dispatch_request()
  File "C:\Users\tiago\AppData\Local\Programs\Python\Python313\Lib\site-packages\flask\app.py", line 919, in full_dispatch_request
    rv = self.handle_user_exception(e)
  File "C:\Users\tiago\AppData\Local\Programs\Python\Python313\Lib\site-packages\flask_cors\extension.py", line 194, in wrapped_function
    return cors_after_request(app.make_response(f(*args, **kwargs)))
                                                ~^^^^^^^^^^^^^^^^^
  File "C:\Users\tiago\AppData\Local\Programs\Python\Python313\Lib\site-packages\flask\app.py", line 917, in full_dispatch_request
    rv = self.dispatch_request()
  File "C:\Users\tiago\AppData\Local\Programs\Python\Python313\Lib\site-packages\flask\app.py", line 902, in dispatch_request
    return self.ensure_sync(self.view_functions[rule.endpoint])(**view_args)  # type: ignore[no-any-return]
           ~~~~~~~~~~~~~~~~~~~~~~~~~~~~~~~~~~~~~~~~~~~~~~~~~~~~^^^^^^^^^^^^^
  File "C:\Users\tiago\AppData\Local\Programs\Python\Python313\Lib\site-packages\flask_openapi3\scaffold.py", line 117, in view_func
    response = func(**func_kwargs)
  File "D:\Tiago\PUCRio\mvp\api_slc\app.py", line 80, in get_produtos
    logger.debug(f"%d produtos encontrados" % len(produtos))
                                              ~~~^^^^^^^^^^
TypeError: object of type 'Query' has no len()
[2024-11-28 23:20:03,605] INFO _log() L97   127.0.0.1 - - [28/Nov/2024 23:20:03] "[35m[1mGET /produtos?id_lista=1 HTTP/1.1[0m" 500 - - call_trace=C:\Users\tiago\AppData\Local\Programs\Python\Python313\Lib\site-packages\werkzeug\_internal.py L97  
[2024-11-28 23:20:18,974] ERROR log_exception() L875  Exception on /produtos [GET] - call_trace=C:\Users\tiago\AppData\Local\Programs\Python\Python313\Lib\site-packages\flask\app.py L875 
Traceback (most recent call last):
  File "C:\Users\tiago\AppData\Local\Programs\Python\Python313\Lib\site-packages\flask\app.py", line 1511, in wsgi_app
    response = self.full_dispatch_request()
  File "C:\Users\tiago\AppData\Local\Programs\Python\Python313\Lib\site-packages\flask\app.py", line 919, in full_dispatch_request
    rv = self.handle_user_exception(e)
  File "C:\Users\tiago\AppData\Local\Programs\Python\Python313\Lib\site-packages\flask_cors\extension.py", line 194, in wrapped_function
    return cors_after_request(app.make_response(f(*args, **kwargs)))
                                                ~^^^^^^^^^^^^^^^^^
  File "C:\Users\tiago\AppData\Local\Programs\Python\Python313\Lib\site-packages\flask\app.py", line 917, in full_dispatch_request
    rv = self.dispatch_request()
  File "C:\Users\tiago\AppData\Local\Programs\Python\Python313\Lib\site-packages\flask\app.py", line 902, in dispatch_request
    return self.ensure_sync(self.view_functions[rule.endpoint])(**view_args)  # type: ignore[no-any-return]
           ~~~~~~~~~~~~~~~~~~~~~~~~~~~~~~~~~~~~~~~~~~~~~~~~~~~~^^^^^^^^^^^^^
  File "C:\Users\tiago\AppData\Local\Programs\Python\Python313\Lib\site-packages\flask_openapi3\scaffold.py", line 117, in view_func
    response = func(**func_kwargs)
  File "D:\Tiago\PUCRio\mvp\api_slc\app.py", line 80, in get_produtos
    logger.debug(f"%d produtos encontrados" % len(produtos))
                                              ~~~^^^^^^^^^^
TypeError: object of type 'Query' has no len()
[2024-11-28 23:20:18,982] INFO _log() L97   127.0.0.1 - - [28/Nov/2024 23:20:18] "[35m[1mGET /produtos?id_lista=1 HTTP/1.1[0m" 500 - - call_trace=C:\Users\tiago\AppData\Local\Programs\Python\Python313\Lib\site-packages\werkzeug\_internal.py L97  
[2024-11-28 23:20:29,366] INFO _log() L97   [31m[1mWARNING: This is a development server. Do not use it in a production deployment. Use a production WSGI server instead.[0m
 * Running on all addresses (0.0.0.0)
 * Running on http://127.0.0.1:5000
 * Running on http://192.168.1.73:5000 - call_trace=C:\Users\tiago\AppData\Local\Programs\Python\Python313\Lib\site-packages\werkzeug\_internal.py L97  
[2024-11-28 23:20:29,367] INFO _log() L97   [33mPress CTRL+C to quit[0m - call_trace=C:\Users\tiago\AppData\Local\Programs\Python\Python313\Lib\site-packages\werkzeug\_internal.py L97  
[2024-11-28 23:20:32,913] INFO _log() L97   127.0.0.1 - - [28/Nov/2024 23:20:32] "GET /produtos?id_lista=1 HTTP/1.1" 200 - - call_trace=C:\Users\tiago\AppData\Local\Programs\Python\Python313\Lib\site-packages\werkzeug\_internal.py L97  
[2024-11-28 23:20:32,958] INFO _log() L97   127.0.0.1 - - [28/Nov/2024 23:20:32] "GET /lista?id=1 HTTP/1.1" 200 - - call_trace=C:\Users\tiago\AppData\Local\Programs\Python\Python313\Lib\site-packages\werkzeug\_internal.py L97  
[2024-11-28 23:20:32,978] INFO _log() L97   127.0.0.1 - - [28/Nov/2024 23:20:32] "GET /lista?id=1 HTTP/1.1" 200 - - call_trace=C:\Users\tiago\AppData\Local\Programs\Python\Python313\Lib\site-packages\werkzeug\_internal.py L97  
[2024-11-28 23:20:38,691] INFO _log() L97   127.0.0.1 - - [28/Nov/2024 23:20:38] "GET /produtos?id_lista=2 HTTP/1.1" 200 - - call_trace=C:\Users\tiago\AppData\Local\Programs\Python\Python313\Lib\site-packages\werkzeug\_internal.py L97  
[2024-11-28 23:21:19,412] INFO _log() L97   127.0.0.1 - - [28/Nov/2024 23:21:19] "GET /produtos?id_lista=2 HTTP/1.1" 200 - - call_trace=C:\Users\tiago\AppData\Local\Programs\Python\Python313\Lib\site-packages\werkzeug\_internal.py L97  
[2024-11-28 23:22:56,298] INFO _log() L97   127.0.0.1 - - [28/Nov/2024 23:22:56] "GET /produtos?id_lista=2 HTTP/1.1" 200 - - call_trace=C:\Users\tiago\AppData\Local\Programs\Python\Python313\Lib\site-packages\werkzeug\_internal.py L97  
[2024-11-28 23:25:31,826] INFO _log() L97   127.0.0.1 - - [28/Nov/2024 23:25:31] "GET /produtos?id_lista=1 HTTP/1.1" 200 - - call_trace=C:\Users\tiago\AppData\Local\Programs\Python\Python313\Lib\site-packages\werkzeug\_internal.py L97  
[2024-11-28 23:25:31,859] INFO _log() L97   127.0.0.1 - - [28/Nov/2024 23:25:31] "GET /lista?id=1 HTTP/1.1" 200 - - call_trace=C:\Users\tiago\AppData\Local\Programs\Python\Python313\Lib\site-packages\werkzeug\_internal.py L97  
[2024-11-28 23:25:31,875] INFO _log() L97   127.0.0.1 - - [28/Nov/2024 23:25:31] "GET /lista?id=1 HTTP/1.1" 200 - - call_trace=C:\Users\tiago\AppData\Local\Programs\Python\Python313\Lib\site-packages\werkzeug\_internal.py L97  
[2024-11-28 23:26:29,564] INFO _log() L97   127.0.0.1 - - [28/Nov/2024 23:26:29] "GET /produtos?id_lista=1 HTTP/1.1" 200 - - call_trace=C:\Users\tiago\AppData\Local\Programs\Python\Python313\Lib\site-packages\werkzeug\_internal.py L97  
[2024-11-28 23:26:29,596] INFO _log() L97   127.0.0.1 - - [28/Nov/2024 23:26:29] "GET /lista?id=1 HTTP/1.1" 200 - - call_trace=C:\Users\tiago\AppData\Local\Programs\Python\Python313\Lib\site-packages\werkzeug\_internal.py L97  
[2024-11-28 23:26:29,604] INFO _log() L97   127.0.0.1 - - [28/Nov/2024 23:26:29] "GET /lista?id=1 HTTP/1.1" 200 - - call_trace=C:\Users\tiago\AppData\Local\Programs\Python\Python313\Lib\site-packages\werkzeug\_internal.py L97  
