[2024-11-28 23:13:54,442] INFO _log() L97   [31m[1mWARNING: This is a development server. Do not use it in a production deployment. Use a production WSGI server instead.[0m
 * Running on all addresses (0.0.0.0)
 * Running on http://127.0.0.1:5000
 * Running on http://192.168.1.73:5000 - call_trace=C:\Users\tiago\AppData\Local\Programs\Python\Python313\Lib\site-packages\werkzeug\_internal.py L97  
[2024-11-28 23:13:54,450] INFO _log() L97   [33mPress CTRL+C to quit[0m - call_trace=C:\Users\tiago\AppData\Local\Programs\Python\Python313\Lib\site-packages\werkzeug\_internal.py L97  
[2024-11-28 23:14:00,751] ERROR log_exception() L875  Exception on /produtos [GET] - call_trace=C:\Users\tiago\AppData\Local\Programs\Python\Python313\Lib\site-packages\flask\app.py L875 
Traceback (most recent call last):
  File "C:\Users\tiago\AppData\Local\Programs\Python\Python313\Lib\site-packages\flask\app.py", line 1511, in wsgi_app
    response = self.full_dispatch_request()
  File "C:\Users\tiago\AppData\Local\Programs\Python\Python313\Lib\site-packages\flask\app.py", line 919, in full_dispatch_request
    rv = self.handle_user_exception(e)
  File "C:\Users\tiago\AppData\Local\Programs\Python\Python313\Lib\site-packages\flask_cors\extension.py", line 194, in wrapped_function
    return cors_after_request(app.make_response(f(*args, **kwargs)))
                                                ~^^^^^^^^^^^^^^^^^
  File "C:\Users\tiago\AppData\Local\Programs\Python\Python313\Lib\site-packages\flask\app.py", line 917, in full_dispatch_request
    rv = self.dispatch_request()
  File "C:\Users\tiago\AppData\Local\Programs\Python\Python313\Lib\site-packages\flask\app.py", line 902, in dispatch_request
    return self.ensure_sync(self.view_functions[rule.endpoint])(**view_args)  # type: ignore[no-any-return]
           ~~~~~~~~~~~~~~~~~~~~~~~~~~~~~~~~~~~~~~~~~~~~~~~~~~~~^^^^^^^^^^^^^
  File "C:\Users\tiago\AppData\Local\Programs\Python\Python313\Lib\site-packages\flask_openapi3\scaffold.py", line 117, in view_func
    response = func(**func_kwargs)
  File "D:\Tiago\PUCRio\mvp\api_slc\app.py", line 80, in get_produtos
    logger.debug(f"%d produtos encontrados" % len(produtos))
                                              ~~~^^^^^^^^^^
TypeError: object of type 'Query' has no len()
[2024-11-28 23:14:01,009] INFO _log() L97   127.0.0.1 - - [28/Nov/2024 23:14:01] "[35m[1mGET /produtos?id_lista2 HTTP/1.1[0m" 500 - - call_trace=C:\Users\tiago\AppData\Local\Programs\Python\Python313\Lib\site-packages\werkzeug\_internal.py L97  
[2024-11-28 23:14:04,987] INFO _log() L97   127.0.0.1 - - [28/Nov/2024 23:14:04] "GET /listas HTTP/1.1" 200 - - call_trace=C:\Users\tiago\AppData\Local\Programs\Python\Python313\Lib\site-packages\werkzeug\_internal.py L97  
[2024-11-28 23:14:10,350] ERROR log_exception() L875  Exception on /produtos [GET] - call_trace=C:\Users\tiago\AppData\Local\Programs\Python\Python313\Lib\site-packages\flask\app.py L875 
Traceback (most recent call last):
  File "C:\Users\tiago\AppData\Local\Programs\Python\Python313\Lib\site-packages\flask\app.py", line 1511, in wsgi_app
    response = self.full_dispatch_request()
  File "C:\Users\tiago\AppData\Local\Programs\Python\Python313\Lib\site-packages\flask\app.py", line 919, in full_dispatch_request
    rv = self.handle_user_exception(e)
  File "C:\Users\tiago\AppData\Local\Programs\Python\Python313\Lib\site-packages\flask_cors\extension.py", line 194, in wrapped_function
    return cors_after_request(app.make_response(f(*args, **kwargs)))
                                                ~^^^^^^^^^^^^^^^^^
  File "C:\Users\tiago\AppData\Local\Programs\Python\Python313\Lib\site-packages\flask\app.py", line 917, in full_dispatch_request
    rv = self.dispatch_request()
  File "C:\Users\tiago\AppData\Local\Programs\Python\Python313\Lib\site-packages\flask\app.py", line 902, in dispatch_request
    return self.ensure_sync(self.view_functions[rule.endpoint])(**view_args)  # type: ignore[no-any-return]
           ~~~~~~~~~~~~~~~~~~~~~~~~~~~~~~~~~~~~~~~~~~~~~~~~~~~~^^^^^^^^^^^^^
  File "C:\Users\tiago\AppData\Local\Programs\Python\Python313\Lib\site-packages\flask_openapi3\scaffold.py", line 117, in view_func
    response = func(**func_kwargs)
  File "D:\Tiago\PUCRio\mvp\api_slc\app.py", line 80, in get_produtos
    logger.debug(f"%d produtos encontrados" % len(produtos))
                                              ~~~^^^^^^^^^^
TypeError: object of type 'Query' has no len()
[2024-11-28 23:14:10,419] INFO _log() L97   127.0.0.1 - - [28/Nov/2024 23:14:10] "[35m[1mGET /produtos?id_lista1 HTTP/1.1[0m" 500 - - call_trace=C:\Users\tiago\AppData\Local\Programs\Python\Python313\Lib\site-packages\werkzeug\_internal.py L97  
[2024-11-28 23:14:14,322] INFO _log() L97   127.0.0.1 - - [28/Nov/2024 23:14:14] "GET /listas HTTP/1.1" 200 - - call_trace=C:\Users\tiago\AppData\Local\Programs\Python\Python313\Lib\site-packages\werkzeug\_internal.py L97  
[2024-11-28 23:15:00,858] INFO _log() L97   [31m[1mWARNING: This is a development server. Do not use it in a production deployment. Use a production WSGI server instead.[0m
 * Running on all addresses (0.0.0.0)
 * Running on http://127.0.0.1:5000
 * Running on http://192.168.1.73:5000 - call_trace=C:\Users\tiago\AppData\Local\Programs\Python\Python313\Lib\site-packages\werkzeug\_internal.py L97  
[2024-11-28 23:15:00,860] INFO _log() L97   [33mPress CTRL+C to quit[0m - call_trace=C:\Users\tiago\AppData\Local\Programs\Python\Python313\Lib\site-packages\werkzeug\_internal.py L97  
[2024-11-28 23:15:04,359] INFO _log() L97   127.0.0.1 - - [28/Nov/2024 23:15:04] "GET /listas HTTP/1.1" 200 - - call_trace=C:\Users\tiago\AppData\Local\Programs\Python\Python313\Lib\site-packages\werkzeug\_internal.py L97  
[2024-11-28 23:15:09,994] INFO _log() L97   127.0.0.1 - - [28/Nov/2024 23:15:09] "GET /produtos?id_lista1 HTTP/1.1" 200 - - call_trace=C:\Users\tiago\AppData\Local\Programs\Python\Python313\Lib\site-packages\werkzeug\_internal.py L97  
[2024-11-28 23:15:10,009] INFO _log() L97   127.0.0.1 - - [28/Nov/2024 23:15:10] "GET /lista?id=1 HTTP/1.1" 200 - - call_trace=C:\Users\tiago\AppData\Local\Programs\Python\Python313\Lib\site-packages\werkzeug\_internal.py L97  
[2024-11-28 23:15:10,023] INFO _log() L97   127.0.0.1 - - [28/Nov/2024 23:15:10] "GET /lista?id=1 HTTP/1.1" 200 - - call_trace=C:\Users\tiago\AppData\Local\Programs\Python\Python313\Lib\site-packages\werkzeug\_internal.py L97  
[2024-11-28 23:15:17,641] INFO _log() L97   127.0.0.1 - - [28/Nov/2024 23:15:17] "GET /produtos?id_lista2 HTTP/1.1" 200 - - call_trace=C:\Users\tiago\AppData\Local\Programs\Python\Python313\Lib\site-packages\werkzeug\_internal.py L97  
[2024-11-28 23:15:17,670] INFO _log() L97   127.0.0.1 - - [28/Nov/2024 23:15:17] "GET /lista?id=1 HTTP/1.1" 200 - - call_trace=C:\Users\tiago\AppData\Local\Programs\Python\Python313\Lib\site-packages\werkzeug\_internal.py L97  
[2024-11-28 23:15:17,681] INFO _log() L97   127.0.0.1 - - [28/Nov/2024 23:15:17] "GET /lista?id=1 HTTP/1.1" 200 - - call_trace=C:\Users\tiago\AppData\Local\Programs\Python\Python313\Lib\site-packages\werkzeug\_internal.py L97  
[2024-11-28 23:15:20,529] INFO _log() L97   127.0.0.1 - - [28/Nov/2024 23:15:20] "GET /produtos?id_lista2 HTTP/1.1" 200 - - call_trace=C:\Users\tiago\AppData\Local\Programs\Python\Python313\Lib\site-packages\werkzeug\_internal.py L97  
[2024-11-28 23:15:20,557] INFO _log() L97   127.0.0.1 - - [28/Nov/2024 23:15:20] "GET /lista?id=1 HTTP/1.1" 200 - - call_trace=C:\Users\tiago\AppData\Local\Programs\Python\Python313\Lib\site-packages\werkzeug\_internal.py L97  
[2024-11-28 23:15:20,581] INFO _log() L97   127.0.0.1 - - [28/Nov/2024 23:15:20] "GET /lista?id=1 HTTP/1.1" 200 - - call_trace=C:\Users\tiago\AppData\Local\Programs\Python\Python313\Lib\site-packages\werkzeug\_internal.py L97  
[2024-11-28 23:17:20,808] INFO _log() L97   [31m[1mWARNING: This is a development server. Do not use it in a production deployment. Use a production WSGI server instead.[0m
 * Running on all addresses (0.0.0.0)
 * Running on http://127.0.0.1:5000
 * Running on http://192.168.1.73:5000 - call_trace=C:\Users\tiago\AppData\Local\Programs\Python\Python313\Lib\site-packages\werkzeug\_internal.py L97  
[2024-11-28 23:17:20,810] INFO _log() L97   [33mPress CTRL+C to quit[0m - call_trace=C:\Users\tiago\AppData\Local\Programs\Python\Python313\Lib\site-packages\werkzeug\_internal.py L97  
